<?xml version="1.0"?>
<robot name="ur5e_shadowhand">
  <gazebo>
    <plugin filename="libgazebo_ros_control.so" name="ros_control">
      <!--robotNamespace>/</robotNamespace-->
      <!--robotSimType>gazebo_ros_control/DefaultRobotHWSim</robotSimType-->
    </plugin>
    <!--
    <plugin name="gazebo_ros_power_monitor_controller" filename="libgazebo_ros_power_monitor.so">
      <alwaysOn>true</alwaysOn>
      <updateRate>1.0</updateRate>
      <timeout>5</timeout>
      <powerStateTopic>power_state</powerStateTopic>
      <powerStateRate>10.0</powerStateRate>
      <fullChargeCapacity>87.78</fullChargeCapacity>     
      <dischargeRate>-474</dischargeRate>
      <chargeRate>525</chargeRate>
      <dischargeVoltage>15.52</dischargeVoltage>
      <chargeVoltage>16.41</chargeVoltage>
    </plugin>
-->
  </gazebo>
  <!-- measured from model -->
  <!--property name="shoulder_height" value="0.089159" /-->
  <!--property name="shoulder_offset" value="0.13585" /-->
  <!-- shoulder_offset - elbow_offset + wrist_1_length = 0.10915 -->
  <!--property name="upper_arm_length" value="0.42500" /-->
  <!--property name="elbow_offset" value="0.1197" /-->
  <!-- CAD measured -->
  <!--property name="forearm_length" value="0.39225" /-->
  <!--property name="wrist_1_length" value="0.093" /-->
  <!-- CAD measured -->
  <!--property name="wrist_2_length" value="0.09465" /-->
  <!-- In CAD this distance is 0.930, but in the spec it is 0.09465 -->
  <!--property name="wrist_3_length" value="0.0823" /-->
  <!-- manually measured -->
<link name="base_link">
    <visual>
      <geometry>
        <mesh filename="../meshes/ur5e/visual/base.dae"/>
      </geometry>
      <material name="LightGrey">
        <color rgba="0.7 0.7 0.7 1.0"/>
      </material>
    </visual>
    <collision>
      <geometry>
        <mesh filename="../meshes/ur5e/collision/base.stl" scale="1.0 1.0 1.0"/>
      </geometry>
    </collision>
    <inertial>
      <mass value="4.0"/>
      <origin rpy="0 0 0" xyz="0.0 0.0 0.0"/>
      <inertia ixx="0.00443333156" ixy="0.0" ixz="0.0" iyy="0.00443333156" iyz="0.0" izz="0.0072"/>
    </inertial>
  </link>
  <joint name="shoulder_pan_joint" type="revolute">
    <parent link="base_link"/>
    <child link="shoulder_link"/>
    <origin rpy="0.0 0.0 0.0" xyz="0.0 0.0 0.163"/>
    <axis xyz="0 0 1"/>
    <limit effort="150.0" lower="-6.28318530718" upper="6.28318530718" velocity="3.14"/>
    <dynamics damping="0.0" friction="0.0"/>
  </joint>
  <link name="shoulder_link">
    <visual>
      <geometry>
        <mesh filename="../meshes/ur5e/visual/shoulder.dae"/>
      </geometry>
      <material name="LightGrey">
        <color rgba="0.7 0.7 0.7 1.0"/>
      </material>
    </visual>
    <collision>
      <geometry>
        <mesh filename="../meshes/ur5e/collision/shoulder.stl" scale="1.0 1.0 1.0"/>
      </geometry>
    </collision>
    <inertial>
      <mass value="3.7"/>
      <origin rpy="0 0 0" xyz="0.0 0.0 0.0"/>
      <inertia ixx="0.010267495893" ixy="0.0" ixz="0.0" iyy="0.010267495893" iyz="0.0" izz="0.00666"/>
    </inertial>
  </link>
  <joint name="shoulder_lift_joint" type="revolute">
    <parent link="shoulder_link"/>
    <child link="upper_arm_link"/>
    <origin rpy="0.0 1.57079632679 0.0" xyz="0.0 0.138 0.0"/>
    <axis xyz="0 1 0"/>
    <limit effort="150.0" lower="-6.28318530718" upper="6.28318530718" velocity="3.14"/>
    <dynamics damping="0.0" friction="0.0"/>
  </joint>
  <link name="upper_arm_link">
    <visual>
      <geometry>
        <mesh filename="../meshes/ur5e/visual/upperarm.dae"/>
      </geometry>
      <material name="LightGrey">
        <color rgba="0.7 0.7 0.7 1.0"/>
      </material>
    </visual>
    <collision>
      <geometry>
        <mesh filename="../meshes/ur5e/collision/upperarm.stl" scale="1.0 1.0 1.0"/>
      </geometry>
    </collision>
    <inertial>
      <mass value="8.393"/>
      <origin rpy="0 0 0" xyz="0.0 0.0 0.2125"/>
      <inertia ixx="0.133885781862" ixy="0.0" ixz="0.0" iyy="0.133885781862" iyz="0.0" izz="0.0151074"/>
    </inertial>
  </link>
  <joint name="elbow_joint" type="revolute">
    <parent link="upper_arm_link"/>
    <child link="forearm_link"/>
    <origin rpy="0.0 0.0 0.0" xyz="0.0 -0.131 0.425"/>
    <axis xyz="0 1 0"/>
    <limit effort="150.0" lower="-3.14159265359" upper="3.14159265359" velocity="3.14"/>
    <dynamics damping="0.0" friction="0.0"/>
  </joint>
  <link name="forearm_link">
    <visual>
      <geometry>
        <mesh filename="../meshes/ur5e/visual/forearm.dae"/>
      </geometry>
      <material name="LightGrey">
        <color rgba="0.7 0.7 0.7 1.0"/>
      </material>
    </visual>
    <collision>
      <geometry>
        <mesh filename="../meshes/ur5e/collision/forearm.stl" scale="1.0 1.0 1.0"/>
      </geometry>
    </collision>
    <inertial>
      <mass value="2.275"/>
      <origin rpy="0 0 0" xyz="0.0 0.0 0.196"/>
      <inertia ixx="0.0311796208615" ixy="0.0" ixz="0.0" iyy="0.0311796208615" iyz="0.0" izz="0.004095"/>
    </inertial>
  </link>
  <joint name="wrist_1_joint" type="revolute">
    <parent link="forearm_link"/>
    <child link="wrist_1_link"/>
    <origin rpy="0.0 1.57079632679 0.0" xyz="0.0 0.0 0.392"/>
    <axis xyz="0 1 0"/>
    <limit effort="28.0" lower="-6.28318530718" upper="6.28318530718" velocity="6.28"/>
    <dynamics damping="0.0" friction="0.0"/>
  </joint>
  <link name="wrist_1_link">
    <visual>
      <geometry>
        <mesh filename="../meshes/ur5e/visual/wrist1.dae"/>
      </geometry>
      <material name="LightGrey">
        <color rgba="0.7 0.7 0.7 1.0"/>
      </material>
    </visual>
    <collision>
      <geometry>
        <mesh filename="../meshes/ur5e/collision/wrist1.stl" scale="1.0 1.0 1.0"/>
      </geometry>
    </collision>
    <inertial>
      <mass value="1.219"/>
      <origin rpy="0 0 0" xyz="0.0 0.127 0.0"/>
      <inertia ixx="0.00255989897604" ixy="0.0" ixz="0.0" iyy="0.00255989897604" iyz="0.0" izz="0.0021942"/>
    </inertial>
  </link>
  <joint name="wrist_2_joint" type="revolute">
    <parent link="wrist_1_link"/>
    <child link="wrist_2_link"/>
    <origin rpy="0.0 0.0 0.0" xyz="0.0 0.127 0.0"/>
    <axis xyz="0 0 1"/>
    <limit effort="28.0" lower="-6.28318530718" upper="6.28318530718" velocity="6.28"/>
    <dynamics damping="0.0" friction="0.0"/>
  </joint>
  <link name="wrist_2_link">
    <visual>
      <geometry>
        <mesh filename="../meshes/ur5e/visual/wrist2.dae"/>
      </geometry>
      <material name="LightGrey">
        <color rgba="0.7 0.7 0.7 1.0"/>
      </material>
    </visual>
    <collision>
      <geometry>
        <mesh filename="../meshes/ur5e/collision/wrist2.stl" scale="1.0 1.0 1.0"/>
      </geometry>
    </collision>
    <inertial>
      <mass value="1.219"/>
      <origin rpy="0 0 0" xyz="0.0 0.0 0.1"/>
      <inertia ixx="0.00255989897604" ixy="0.0" ixz="0.0" iyy="0.00255989897604" iyz="0.0" izz="0.0021942"/>
    </inertial>
  </link>
  <joint name="wrist_3_joint" type="revolute">
    <parent link="wrist_2_link"/>
    <child link="wrist_3_link"/>
    <origin rpy="0.0 0.0 0.0" xyz="0.0 0.0 0.1"/>
    <axis xyz="0 1 0"/>
    <limit effort="28.0" lower="-6.28318530718" upper="6.28318530718" velocity="6.28"/>
    <dynamics damping="0.0" friction="0.0"/>
  </joint>
  <link name="wrist_3_link">
    <visual>
      <geometry>
        <mesh filename="../meshes/ur5e/visual/wrist3.dae"/>
      </geometry>
      <material name="LightGrey">
        <color rgba="0.7 0.7 0.7 1.0"/>
      </material>
    </visual>
    <collision>
      <geometry>
        <mesh filename="../meshes/ur5e/collision/wrist3.stl" scale="1.0 1.0 1.0"/>
      </geometry>
    </collision>
    <inertial>
      <mass value="0.1879"/>
      <origin rpy="1.57079632679 0 0" xyz="0.0 0.0771 0.0"/>
      <inertia ixx="9.89041005217e-05" ixy="0.0" ixz="0.0" iyy="9.89041005217e-05" iyz="0.0" izz="0.0001321171875"/>
    </inertial>
  </link>
  <joint name="ee_fixed_joint" type="fixed">
    <parent link="wrist_3_link"/>
    <child link="ee_link"/>
    <origin rpy="0.0 0.0 1.57079632679" xyz="0.0 0.1 0.0"/>
  </joint>
  <link name="ee_link">
    <collision>
      <geometry>
        <box size="0.01 0.01 0.01"/>
      </geometry>
      <origin rpy="0 0 0" xyz="-0.01 0 0"/>
    </collision>
  </link>
  <transmission name="shoulder_pan_trans">
    <type>transmission_interface/SimpleTransmission</type>
    <joint name="shoulder_pan_joint">
      <hardwareInterface>hardware_interface/PositionJointInterface</hardwareInterface>
    </joint>
    <actuator name="shoulder_pan_motor">
      <mechanicalReduction>1</mechanicalReduction>
    </actuator>
  </transmission>
  <transmission name="shoulder_lift_trans">
    <type>transmission_interface/SimpleTransmission</type>
    <joint name="shoulder_lift_joint">
      <hardwareInterface>hardware_interface/PositionJointInterface</hardwareInterface>
    </joint>
    <actuator name="shoulder_lift_motor">
      <mechanicalReduction>1</mechanicalReduction>
    </actuator>
  </transmission>
  <transmission name="elbow_trans">
    <type>transmission_interface/SimpleTransmission</type>
    <joint name="elbow_joint">
      <hardwareInterface>hardware_interface/PositionJointInterface</hardwareInterface>
    </joint>
    <actuator name="elbow_motor">
      <mechanicalReduction>1</mechanicalReduction>
    </actuator>
  </transmission>
  <transmission name="wrist_1_trans">
    <type>transmission_interface/SimpleTransmission</type>
    <joint name="wrist_1_joint">
      <hardwareInterface>hardware_interface/PositionJointInterface</hardwareInterface>
    </joint>
    <actuator name="wrist_1_motor">
      <mechanicalReduction>1</mechanicalReduction>
    </actuator>
  </transmission>
  <transmission name="wrist_2_trans">
    <type>transmission_interface/SimpleTransmission</type>
    <joint name="wrist_2_joint">
      <hardwareInterface>hardware_interface/PositionJointInterface</hardwareInterface>
    </joint>
    <actuator name="wrist_2_motor">
      <mechanicalReduction>1</mechanicalReduction>
    </actuator>
  </transmission>
  <transmission name="wrist_3_trans">
    <type>transmission_interface/SimpleTransmission</type>
    <joint name="wrist_3_joint">
      <hardwareInterface>hardware_interface/PositionJointInterface</hardwareInterface>
    </joint>
    <actuator name="wrist_3_motor">
      <mechanicalReduction>1</mechanicalReduction>
    </actuator>
  </transmission>
  <gazebo reference="shoulder_link">
    <selfCollide>true</selfCollide>
  </gazebo>
  <gazebo reference="upper_arm_link">
    <selfCollide>true</selfCollide>
  </gazebo>
  <gazebo reference="forearm_link">
    <selfCollide>true</selfCollide>
  </gazebo>
  <gazebo reference="wrist_1_link">
    <selfCollide>true</selfCollide>
  </gazebo>
  <gazebo reference="wrist_3_link">
    <selfCollide>true</selfCollide>
  </gazebo>
  <gazebo reference="wrist_2_link">
    <selfCollide>true</selfCollide>
  </gazebo>
  <gazebo reference="ee_link">
    <selfCollide>true</selfCollide>
  </gazebo>
  <!-- ROS base_link to UR 'Base' Coordinates transform -->
  <link name="base"/>
  <joint name="base_link-base_fixed_joint" type="fixed">
    <!-- NOTE: this rotation is only needed as long as base_link itself is
                not corrected wrt the real robot (ie: rotated over 180
                degrees)
      -->
    <origin rpy="0 0 -3.14159265359" xyz="0 0 0"/>
    <parent link="base_link"/>
    <child link="base"/>
  </joint>
  <!-- Frame coincident with all-zeros TCP on UR controller -->
  <link name="tool0"/>
  <joint name="wrist_3_link-tool0_fixed_joint" type="fixed">
    <origin rpy="-1.57079632679 0 0" xyz="0 0.1 0"/>
    <parent link="wrist_3_link"/>
    <child link="tool0"/>
  </joint>
  <link name="world"/>
  <joint name="world_joint" type="fixed">
    <parent link="world"/>
    <child link="base_link"/>
    <origin rpy="0.0 0.0 0.0" xyz="0.0 0.0 0.0"/>
  </joint>
  <joint name="ur5e_shadow_forearm_fixed" type="fixed">
    <parent link="wrist_3_link"/>
    <child  link="sh_forearm"/>
    <!-- 这里的外参要你根据实际视觉效果微调 -->
    <origin xyz="0 0.095 0" rpy="-1.571 -1.571 0"/>
  </joint>
  <!-- 这里面放：UR5e 的 link/joint/transmission + ShadowHand 的 link/joint + 中间连接 joint -->
  <!-- Forearm-Wrist-Palm Links -->
    <link name="sh_forearm">
        <visual>
            <geometry name="sh_forearm_visual">
                <mesh filename="../shadow_hand_ign/shadow_hand/meshes/visual/sh_forearm.dae"/>
            </geometry>
        </visual>
        <collision>
            <geometry name="sh_forearm_collision">
                <mesh filename="../shadow_hand_ign/shadow_hand/meshes/collision/sh_forearm.stl"/>
            </geometry>
        </collision>
    </link>

    <link name="wrist">
        <visual>
            <geometry name="wrist_visual">
                <mesh filename="../shadow_hand_ign/shadow_hand/meshes/visual/wrist.dae"/>
            </geometry>
        </visual>
        <collision>
            <geometry name="wrist_collision">
                <mesh filename="../shadow_hand_ign/shadow_hand/meshes/collision/wrist.stl"/>
            </geometry>
        </collision>
    </link>

    <link name="palm">
        <visual>
            <geometry name="palm_visual">
                <mesh filename="../shadow_hand_ign/shadow_hand/meshes/visual/palm.dae"/>
            </geometry>
        </visual>
        <collision>
            <geometry name="palm_collision">
                <mesh filename="../shadow_hand_ign/shadow_hand/meshes/collision/palm.stl"/>
            </geometry>
        </collision>
    </link>


    <!-- Forearm-Wrist Joints -->
    <joint name="forearm_joint" type="revolute">
        <parent link="sh_forearm"/>
        <child link="wrist"/>
        <origin rpy="0 0 0" xyz="0 -0.010 0.213"/>
        <axis xyz="0 1 0"/>
        <limit effort="10.0" lower="-0.523598775598" upper="0.174532925199" velocity="2.0"/>
    </joint>

    <joint name="wrist_joint" type="revolute">
        <parent link="wrist"/>
        <child link="palm"/>
        <origin rpy="0 0 0" xyz="0 0 0.034"/>
        <axis xyz="1 0 0"/>
        <limit effort="5.0" lower="-0.698131700798" upper="0.488692190558" velocity="2.0"/>
    </joint>


    <!-- Thumb Links -->
    <link name="thumb_base"/>

    <link name="thumb_proximal">
        <visual>
            <geometry name="thumb_proximal_visual">
                <mesh filename="../shadow_hand_ign/shadow_hand/meshes/visual/thumb_proximal.dae"/>
            </geometry>
        </visual>
        <collision>
            <geometry name="thumb_proximal_collision">
                <mesh filename="../shadow_hand_ign/shadow_hand/meshes/collision/thumb_proximal.stl"/>
            </geometry>
        </collision>
    </link>

    <link name="thumb_hub"/>

    <link name="thumb_middle">
        <visual>
            <geometry name="thumb_middle_visual">
                <mesh filename="../shadow_hand_ign/shadow_hand/meshes/visual/thumb_middle.dae"/>
            </geometry>
        </visual>
        <collision>
            <geometry name="thumb_middle_collision">
                <mesh filename="../shadow_hand_ign/shadow_hand/meshes/collision/thumb_middle.stl"/>
            </geometry>
        </collision>
    </link>

    <link name="thumb_distal">
        <visual>
            <geometry name="thumb_distal_visual">
                <mesh filename="../shadow_hand_ign/shadow_hand/meshes/visual/thumb_distal.dae"/>
            </geometry>
        </visual>
        <collision>
            <geometry name="thumb_distal_collision">
                <mesh filename="../shadow_hand_ign/shadow_hand/meshes/collision/thumb_distal.stl"/>
            </geometry>
        </collision>
    </link>


    <!-- Thumb Joints -->
    <joint name="thumb_joint1" type="revolute">
        <parent link="palm"/>
        <child link="thumb_base"/>
        <origin rpy="0 0.785398163397 0.0" xyz="0.034 -0.0085 0.029"/>
        <axis xyz="0 0 -1"/>
        <limit effort="4.0" lower="-1.0471975512" upper="1.0471975512" velocity="4.0"/>
    </joint>

    <joint name="thumb_joint2" type="revolute">
        <parent link="thumb_base"/>
        <child link="thumb_proximal"/>
        <axis xyz="1 0 0"/>
        <limit effort="4.0" lower="0.0" upper="1.2217304764" velocity="4.0"/>
    </joint>

    <joint name="thumb_joint3" type="revolute">
        <parent link="thumb_proximal"/>
        <child link="thumb_hub"/>
        <origin rpy="0 0 0" xyz="0 0 0.038"/>
        <axis xyz="1 0 0"/>
        <limit effort="4.0" lower="-0.209439510239" upper="0.209439510239" velocity="4.0"/>
    </joint>

    <joint name="thumb_joint4" type="revolute">
        <parent link="thumb_hub"/>
        <child link="thumb_middle"/>
        <axis xyz="0 -1 0"/>
        <limit effort="4.0" lower="-0.698131700798" upper="0.698131700798" velocity="2.0"/>
    </joint>

    <joint name="thumb_joint5" type="revolute">
        <parent link="thumb_middle"/>
        <child link="thumb_distal"/>
        <origin rpy="0 0 -1.57079632679" xyz="0 0 0.032"/>
        <axis xyz="1 0 0"/>
        <limit effort="4.0" lower="0" upper="1.57079632679" velocity="4.0"/>
    </joint>


    <!-- Index Finger Links -->
    <link name="index_finger_knuckle">
        <visual>
            <origin rpy="0 0 0" xyz="0 0 0.0005"/>
            <geometry name="index_finger_knuckle_visual">
                <mesh filename="../shadow_hand_ign/shadow_hand/meshes/visual/knuckle.dae"/>
            </geometry>
        </visual>
        <collision>
            <origin rpy="0 0 0" xyz="0 0 0.0005"/>
            <geometry name="index_finger_knuckle_collision">
                <mesh filename="../shadow_hand_ign/shadow_hand/meshes/collision/knuckle.stl"/>
            </geometry>
        </collision>
    </link>

    <link name="index_finger_proximal">
        <visual>
            <geometry name="index_finger_proximal_visual">
                <mesh filename="../shadow_hand_ign/shadow_hand/meshes/visual/finger_proximal.dae"/>
            </geometry>
        </visual>
        <collision>
            <geometry name="index_finger_proximal_collision">
                <mesh filename="../shadow_hand_ign/shadow_hand/meshes/collision/finger_proximal.stl"/>
            </geometry>
        </collision>
    </link>

    <link name="index_finger_middle">
        <visual>
            <geometry name="index_finger_middle_visual">
                <mesh filename="../shadow_hand_ign/shadow_hand/meshes/visual/finger_middle.dae"/>
            </geometry>
        </visual>
        <collision>
            <geometry name="index_finger_middle_collision">
                <mesh filename="../shadow_hand_ign/shadow_hand/meshes/collision/finger_middle.stl"/>
            </geometry>
        </collision>
    </link>

    <link name="index_finger_distal">
        <visual>
            <geometry name="index_finger_distal_visual">
                <mesh filename="../shadow_hand_ign/shadow_hand/meshes/visual/finger_distal.dae"/>
            </geometry>
        </visual>
        <collision>
            <geometry name="index_finger_distal_collision">
                <mesh filename="../shadow_hand_ign/shadow_hand/meshes/collision/finger_distal.stl"/>
            </geometry>
        </collision>
    </link>


    <!-- Index Finger Joints -->
    <joint name="index_finger_joint1" type="revolute">
        <parent link="palm"/>
        <child link="index_finger_knuckle"/>
        <origin rpy="0 0 0" xyz="0.033 0 0.095"/>
        <axis xyz="0 -1 0"/>
        <limit effort="4.0" lower="-0.349065850399" upper="0.349065850399" velocity="2.0"/>
    </joint>

    <joint name="index_finger_join2" type="revolute">
        <parent link="index_finger_knuckle"/>
        <child link="index_finger_proximal"/>
        <axis xyz="1 0 0"/>
        <limit effort="4.0" lower="0" upper="1.57079632679" velocity="2.0"/>
    </joint>

    <joint name="index_finger_joint3" type="revolute">
        <parent link="index_finger_proximal"/>
        <child link="index_finger_middle"/>
        <origin rpy="0 0 0" xyz="0 0 0.045"/>
        <axis xyz="1 0 0"/>
        <limit effort="4.0" lower="0" upper="1.57079632679" velocity="2.0"/>
    </joint>

    <joint name="index_finger_joint4" type="revolute">
        <parent link="index_finger_middle"/>
        <child link="index_finger_distal"/>
        <origin rpy="0 0 0" xyz="0 0 0.025"/>
        <axis xyz="1 0 0"/>
        <limit effort="4.0" lower="0" upper="1.57079632679" velocity="2.0"/>
    </joint>


    <!-- Middle Finger Links -->
    <link name="middle_finger_knuckle">
        <visual>
            <origin rpy="0 0 0" xyz="0 0 0.0005"/>
            <geometry name="middle_finger_knuckle_visual">
                <mesh filename="../shadow_hand_ign/shadow_hand/meshes/visual/knuckle.dae"/>
            </geometry>
        </visual>
        <collision>
            <origin rpy="0 0 0" xyz="0 0 0.0005"/>
            <geometry name="middle_finger_knuckle_collision">
                <mesh filename="../shadow_hand_ign/shadow_hand/meshes/collision/knuckle.stl"/>
            </geometry>
        </collision>
    </link>

    <link name="middle_finger_proximal">
        <visual>
            <geometry name="middle_finger_proximal_visual">
                <mesh filename="../shadow_hand_ign/shadow_hand/meshes/visual/finger_proximal.dae"/>
            </geometry>
        </visual>
        <collision>
            <geometry name="middle_finger_proximal_collision">
                <mesh filename="../shadow_hand_ign/shadow_hand/meshes/collision/finger_proximal.stl"/>
            </geometry>
        </collision>
    </link>

    <link name="middle_finger_middle">
        <visual>
            <geometry name="middle_finger_middle_visual">
                <mesh filename="../shadow_hand_ign/shadow_hand/meshes/visual/finger_middle.dae"/>
            </geometry>
        </visual>
        <collision>
            <geometry name="middle_finger_middle_collision">
                <mesh filename="../shadow_hand_ign/shadow_hand/meshes/collision/finger_middle.stl"/>
            </geometry>
        </collision>
    </link>

    <link name="middle_finger_distal">
        <visual>
            <geometry name="middle_finger_distal_visual">
                <mesh filename="../shadow_hand_ign/shadow_hand/meshes/visual/finger_distal.dae"/>
            </geometry>
        </visual>
        <collision>
            <geometry name="middle_finger_distal_collision">
                <mesh filename="../shadow_hand_ign/shadow_hand/meshes/collision/finger_distal.stl"/>
            </geometry>
        </collision>
    </link>


    <!-- Middle Finger Joints -->
    <joint name="middle_finger_joint1" type="revolute">
        <parent link="palm"/>
        <child link="middle_finger_knuckle"/>
        <origin rpy="0 0 0" xyz="0.011 0 0.099"/>
        <axis xyz="0 -1 0"/>
        <limit effort="4.0" lower="-0.349065850399" upper="0.349065850399" velocity="2.0"/>
    </joint>

    <joint name="middle_finger_joint2" type="revolute">
        <parent link="middle_finger_knuckle"/>
        <child link="middle_finger_proximal"/>
        <axis xyz="1 0 0"/>
        <limit effort="4.0" lower="0" upper="1.57079632679" velocity="2.0"/>
    </joint>

    <joint name="middle_finger_joint3" type="revolute">
        <parent link="middle_finger_proximal"/>
        <child link="middle_finger_middle"/>
        <origin rpy="0 0 0" xyz="0 0 0.045"/>
        <axis xyz="1 0 0"/>
        <limit effort="4.0" lower="0" upper="1.57079632679" velocity="2.0"/>
    </joint>

    <joint name="middle_finger_joint4" type="revolute">
        <parent link="middle_finger_middle"/>
        <child link="middle_finger_distal"/>
        <origin rpy="0 0 0" xyz="0 0 0.025"/>
        <axis xyz="1 0 0"/>
        <limit effort="4.0" lower="0" upper="1.57079632679" velocity="2.0"/>
    </joint>


    <!-- Ring Finger Links -->
    <link name="ring_finger_knuckle">
        <visual>
            <origin rpy="0 0 0" xyz="0 0 0.0005"/>
            <geometry name="ring_finger_knuckle_visual">
                <mesh filename="package://shadow_hand_ign/meshes/visual/knuckle.dae"/>
            </geometry>
        </visual>
        <collision>
            <origin rpy="0 0 0" xyz="0 0 0.0005"/>
            <geometry name="ring_finger_knuckle_collision">
                <mesh filename="package://shadow_hand_ign/meshes/collision/knuckle.stl"/>
            </geometry>
        </collision>
    </link>

    <link name="ring_finger_proximal">
        <visual>
            <geometry name="ring_finger_proximal_visual">
                <mesh filename="package://shadow_hand_ign/meshes/visual/finger_proximal.dae"/>
            </geometry>
        </visual>
        <collision>
            <geometry name="ring_finger_proximal_collision">
                <mesh filename="package://shadow_hand_ign/meshes/collision/finger_proximal.stl"/>
            </geometry>
        </collision>
    </link>

    <link name="ring_finger_middle">
        <visual>
            <geometry name="ring_finger_middle_visual">
                <mesh filename="package://shadow_hand_ign/meshes/visual/finger_middle.dae"/>
            </geometry>
        </visual>
        <collision>
            <geometry name="ring_finger_middle_collision">
                <mesh filename="package://shadow_hand_ign/meshes/collision/finger_middle.stl"/>
            </geometry>
        </collision>
    </link>

    <link name="ring_finger_distal">
        <visual>
            <geometry name="ring_finger_distal_visual">
                <mesh filename="package://shadow_hand_ign/meshes/visual/finger_distal.dae"/>
            </geometry>
        </visual>
        <collision>
            <geometry name="ring_finger_distal_collision">
                <mesh filename="package://shadow_hand_ign/meshes/collision/finger_distal.stl"/>
            </geometry>
        </collision>
    </link>


    <!-- Ring Finger Joints -->
    <joint name="ring_finger_joint1" type="revolute">
        <parent link="palm"/>
        <child link="ring_finger_knuckle"/>
        <origin rpy="0 0 0" xyz="-0.011 0 0.095"/>
        <axis xyz="0 1 0"/>
        <limit effort="4.0" lower="-0.349065850399" upper="0.349065850399" velocity="2.0"/>
    </joint>

    <joint name="ring_finger_joint2" type="revolute">
        <parent link="ring_finger_knuckle"/>
        <child link="ring_finger_proximal"/>
        <axis xyz="1 0 0"/>
        <limit effort="4.0" lower="0" upper="1.57079632679" velocity="2.0"/>
    </joint>

    <joint name="ring_finger_joint3" type="revolute">
        <parent link="ring_finger_proximal"/>
        <child link="ring_finger_middle"/>
        <origin rpy="0 0 0" xyz="0 0 0.045"/>
        <axis xyz="1 0 0"/>
        <limit effort="4.0" lower="0" upper="1.57079632679" velocity="2.0"/>
    </joint>

    <joint name="ring_finger_joint4" type="revolute">
        <parent link="ring_finger_middle"/>
        <child link="ring_finger_distal"/>
        <origin rpy="0 0 0" xyz="0 0 0.025"/>
        <axis xyz="1 0 0"/>
        <limit effort="4.0" lower="0" upper="1.57079632679" velocity="2.0"/>
    </joint>


    <!-- Little Finger Links -->
    <link name="little_finger_metacarpal">
        <visual>
            <geometry name="little_finger_metacarpal_visual">
                <mesh filename="package://shadow_hand_ign/meshes/visual/metacarpal.dae"/>
            </geometry>
        </visual>
        <collision>
            <geometry name="little_finger_metacarpal_collision">
                <mesh filename="package://shadow_hand_ign/meshes/collision/metacarpal.stl"/>
            </geometry>
        </collision>
    </link>

    <link name="little_finger_knuckle">
        <visual>
            <origin rpy="0 0 0" xyz="0 0 0.0005"/>
            <geometry name="little_finger_knuckle_visual">
                <mesh filename="package://shadow_hand_ign/meshes/visual/knuckle.dae"/>
            </geometry>
        </visual>
        <collision>
            <origin rpy="0 0 0" xyz="0 0 0.0005"/>
            <geometry name="little_finger_knuckle_collision">
                <mesh filename="package://shadow_hand_ign/meshes/collision/knuckle.stl"/>
            </geometry>
        </collision>
    </link>

    <link name="little_finger_proximal">
        <visual>
            <geometry name="little_finger_proximal_visual">
                <mesh filename="package://shadow_hand_ign/meshes/visual/finger_proximal.dae"/>
            </geometry>
        </visual>
        <collision>
            <geometry name="little_finger_proximal_collision">
                <mesh filename="package://shadow_hand_ign/meshes/collision/finger_proximal.stl"/>
            </geometry>
        </collision>
    </link>

    <link name="little_finger_middle">
        <visual>
            <geometry name="little_finger_middle_visual">
                <mesh filename="package://shadow_hand_ign/meshes/visual/finger_middle.dae"/>
            </geometry>
        </visual>
        <collision>
            <geometry name="little_finger_middle_collision">
                <mesh filename="package://shadow_hand_ign/meshes/collision/finger_middle.stl"/>
            </geometry>
        </collision>
    </link>

    <link name="little_finger_distal">
        <visual>
            <geometry name="little_finger_distal_visual">
                <mesh filename="package://shadow_hand_ign/meshes/visual/finger_distal.dae"/>
            </geometry>
        </visual>
        <collision>
            <geometry name="little_finger_distal_collision">
                <mesh filename="package://shadow_hand_ign/meshes/collision/finger_distal.stl"/>
            </geometry>
        </collision>
    </link>


    <!-- Little Finger Joints -->
    <joint name="little_finger_joint1" type="revolute">
        <parent link="palm"/>
        <child link="little_finger_metacarpal"/>
        <origin rpy="0 0 0" xyz="-0.033 0 0.02071"/>
        <axis xyz="0.573576436 0 0.819152044"/>
        <limit effort="4.0" lower="0" upper="0.785398163397" velocity="2.0"/>
    </joint>

    <joint name="little_finger_joint2" type="revolute">
        <parent link="little_finger_metacarpal"/>
        <child link="little_finger_knuckle"/>
        <origin rpy="0 0 0" xyz="0 0 0.06579"/>
        <axis xyz="0 1 0"/>
        <limit effort="4.0" lower="-0.349065850399" upper="0.349065850399" velocity="2.0"/>
    </joint>

    <joint name="little_finger_joint3" type="revolute">
        <parent link="little_finger_knuckle"/>
        <child link="little_finger_proximal"/>
        <axis xyz="1 0 0"/>
        <limit effort="4.0" lower="0" upper="1.57079632679" velocity="2.0"/>
    </joint>

    <joint name="little_finger_joint4" type="revolute">
        <parent link="little_finger_proximal"/>
        <child link="little_finger_middle"/>
        <origin rpy="0 0 0" xyz="0 0 0.045"/>
        <axis xyz="1 0 0"/>
        <limit effort="4.0" lower="0" upper="1.57079632679" velocity="2.0"/>
    </joint>

    <joint name="little_finger_joint5" type="revolute">
        <parent link="little_finger_middle"/>
        <child link="little_finger_distal"/>
        <origin rpy="0 0 0" xyz="0 0 0.025"/>
        <axis xyz="1 0 0"/>
        <limit effort="4.0" lower="0" upper="1.57079632679" velocity="2.0"/>
    </joint>

</robot>